<?xml version="1.0" ?>
<!-- =================================================================================== -->
<!-- |    This document was autogenerated by xacro from xacro/iri_wam_gazebo.urdf.xacro | -->
<!-- |    EDITING THIS FILE BY HAND IS NOT RECOMMENDED                                 | -->
<!-- =================================================================================== -->
<robot name="iri_wam" xmlns:xacro="http://www.ros.org/wiki/xacro">
  <!-- ros_control plugin -->
  <gazebo>
    <plugin filename="libgazebo_ros_control.so" name="gazebo_ros_control">
      <alwaysOn>true</alwaysOn>
      <updateRate>1000.0</updateRate>
      <robotParam>robot_description</robotParam>
      <robotNamespace>/iri_wam</robotNamespace>
    </plugin>
  </gazebo>
  <link name="world"/>
  <joint name="fixed" type="fixed">
    <parent link="world"/>
    <child link="iri_wam_link_footprint"/>
  </joint>
  <!-- Set up definitions of parts of the robot body -->
  <!-- The first use of a macro. This one was defined in wambase.urdf.xacro above.
       A macro like this will expand to a set of link and joint definitions, and to additional
       Gazebo-related extensions (sensor plugins, etc).  The macro takes an argument, name, 
       that equals "wam", and uses it to generate names for its component links and joints 
       (e.g., wam_link_base).  The included origin block is also an argument to the macro.  By convention, 
       the origin block defines where the component is w.r.t its parent (in this case the parent 
       is the world frame). For more, see http://www.ros.org/wiki/xacro -->
  <link name="iri_wam_link_base">
    <inertial>
      <mass value="20"/>
      <origin xyz="0.0 0.0 0.0"/>
      <inertia ixx="1.0" ixy="0.0" ixz="0.0" iyy="1.0" iyz="0.0" izz="1.0"/>
    </inertial>
    <visual>
      <origin rpy="0 0 0" xyz="0 0 0"/>
      <geometry>
        <mesh filename="package://iri_wam_description/mesh/wambase.stl" scale="1.0 1.0 1.0"/>
      </geometry>
      <material name="Grey">
        <color rgba="0.75 0.75 0.75 1.0"/>
      </material>
    </visual>
    <collision>
      <origin rpy="0 0 0" xyz="0.0 0.0 0.0"/>
      <geometry>
        <mesh filename="package://iri_wam_description/mesh/wambase_collision.stl" scale="1.0 1.0 1.0"/>
      </geometry>
      <contact_coefficients kd="1.0" kp="1000.0" mu="0"/>
    </collision>
  </link>
  <link name="iri_wam_link_footprint"/>
  <joint name="iri_wam_joint_footprint" type="fixed">
    <origin rpy="0 0 0" xyz="0.22 0.14 0.346"/>
    <child link="iri_wam_link_base"/>
    <parent link="iri_wam_link_footprint"/>
  </joint>
  <gazebo reference="iri_wam_link_base">
    <selfCollide>true</selfCollide>
    <material>Gazebo/Grey</material>
  </gazebo>
  <link name="iri_wam_link_1">
    <inertial>
      <mass value="8.3936"/>
      <origin rpy="0 0 0" xyz="0.0 0.0 0.0"/>
      <inertia ixx="1.0" ixy="0.0" ixz="0.0" iyy="1.0" iyz="0.0" izz="1.0"/>
    </inertial>
    <visual>
      <origin rpy="0 0 0" xyz="0.0 0.0 0.0"/>
      <geometry name="iri_wam_link_1_visual">
        <mesh filename="package://iri_wam_description/mesh/wam1.stl" scale="1.0 1.0 1.0"/>
      </geometry>
      <material name="Grey">
        <color rgba="0.75 0.75 0.75 1.0"/>
      </material>
    </visual>
    <collision>
      <origin rpy="0 0 0" xyz="0.0 0.0 0.0"/>
      <geometry name="iri_wam_link_1_collision">
        <mesh filename="package://iri_wam_description/mesh/wam1_collision.stl" scale="1.0 1.0 1.0"/>
        <!--                <box size="0.20 0.40 0.40"/> -->
      </geometry>
      <contact_coefficients kd="1.0" kp="1000.0" mu="0"/>
    </collision>
  </link>
  <gazebo reference="iri_wam_link_1">
    <material>Gazebo/Grey</material>
    <selfCollide>true</selfCollide>
  </gazebo>
  <joint name="iri_wam_joint_1" type="revolute">
    <parent link="iri_wam_link_base"/>
    <child link="iri_wam_link_1"/>
    <origin rpy="0 0 0" xyz="0.0 0.0 0.0"/>
    <axis xyz="0 0 1"/>
    <limit effort="30" lower="-2.6" upper="2.6" velocity="2.0"/>
    <!-- <safety_controller k_velocity="0.5"/> -->
    <dynamics damping="100"/>
  </joint>
  <transmission name="tran_1">
    <type>transmission_interface/SimpleTransmission</type>
    <joint name="iri_wam_joint_1"/>
    <actuator name="motor_1">
      <hardwareInterface>PositionJointInterface</hardwareInterface>
      <mechanicalReduction>1</mechanicalReduction>
      <motorTorqueConstant>1</motorTorqueConstant>
      <!-- <pulsesPerRevolution>90000</pulsesPerRevolution> -->
    </actuator>
  </transmission>
  <link name="iri_wam_link_2">
    <inertial>
      <mass value="4.8487"/>
      <origin rpy="0 0 0" xyz="0 0 0"/>
      <inertia ixx="1.0" ixy="0.0" ixz="0.0" iyy="1.0" iyz="0.0" izz="1.0"/>
    </inertial>
    <visual>
      <origin rpy="0 0 0" xyz="0.0 0.0 0.0"/>
      <geometry name="iri_wam_link_2_visual">
        <mesh filename="package://iri_wam_description/mesh/wam2.stl" scale="1.0 1.0 1.0"/>
      </geometry>
      <material name="Grey">
        <color rgba="0.75 0.75 0.75 1.0"/>
      </material>
    </visual>
    <collision>
      <origin rpy="0 0 0" xyz="0.0 0.0 0.0"/>
      <geometry name="iri_wam_link_2_collision">
        <mesh filename="package://iri_wam_description/mesh/wam2_collision.stl" scale="1.0 1.0 1.0"/>
        <!--                <box size="0.10 0.10 0.10"/> -->
      </geometry>
      <contact_coefficients kd="1.0" kp="1000.0" mu="0"/>
    </collision>
  </link>
  <gazebo reference="iri_wam_link_2">
    <material>Gazebo/Grey</material>
    <selfCollide>true</selfCollide>
  </gazebo>
  <joint name="iri_wam_joint_2" type="revolute">
    <parent link="iri_wam_link_1"/>
    <child link="iri_wam_link_2"/>
    <origin rpy="0 0 0" xyz="0.0 0.0 0.0"/>
    <axis xyz="0 1 0"/>
    <limit effort="30" lower="-2.0" upper="2.0" velocity="0.5"/>
    <!-- <safety_controller k_velocity="0.5"/> -->
    <dynamics damping="100"/>
  </joint>
  <transmission name="tran_2">
    <type>transmission_interface/SimpleTransmission</type>
    <joint name="iri_wam_joint_2"/>
    <actuator name="motor_2">
      <hardwareInterface>PositionJointInterface</hardwareInterface>
      <mechanicalReduction>1</mechanicalReduction>
      <motorTorqueConstant>1</motorTorqueConstant>
      <!-- <pulsesPerRevolution>90000</pulsesPerRevolution> -->
    </actuator>
  </transmission>
  <link name="iri_wam_link_3">
    <inertial>
      <mass value="1.7251"/>
      <origin rpy="0 0 0" xyz="0 0 0.225"/>
      <inertia ixx="1.0" ixy="0.0" ixz="0.0" iyy="1.0" iyz="0.0" izz="1.0"/>
    </inertial>
    <visual>
      <origin rpy="0 0 0" xyz="0.0 0.0 0.0"/>
      <geometry name="iri_wam_link_3_visual">
        <mesh filename="package://iri_wam_description/mesh/wam3.stl" scale="1.0 1.0 1.0"/>
      </geometry>
      <material name="Grey">
        <color rgba="0.75 0.75 0.75 1.0"/>
      </material>
    </visual>
    <collision>
      <origin rpy="0 0 0" xyz="0.0 0.0 0.0"/>
      <geometry name="iri_wam_link_3_collision">
        <mesh filename="package://iri_wam_description/mesh/wam3_collision.stl" scale="1.0 1.0 1.0"/>
        <!--                <cylinder length="0.6" radius="0.02"/> -->
      </geometry>
      <contact_coefficients kd="1.0" kp="1000.0" mu="0"/>
    </collision>
  </link>
  <gazebo reference="iri_wam_link_3">
    <material>Gazebo/Grey</material>
    <selfCollide>true</selfCollide>
  </gazebo>
  <joint name="iri_wam_joint_3" type="revolute">
    <parent link="iri_wam_link_2"/>
    <child link="iri_wam_link_3"/>
    <origin rpy="0 0 0" xyz="0.0 0.0 0.0"/>
    <axis xyz="0 0 1"/>
    <limit effort="30" lower="-2.8" upper="2.8" velocity="0.5"/>
    <!-- <safety_controller k_velocity="0.5"/> -->
    <dynamics damping="100"/>
  </joint>
  <transmission name="tran_3">
    <type>transmission_interface/SimpleTransmission</type>
    <joint name="iri_wam_joint_3"/>
    <actuator name="motor_3">
      <hardwareInterface>PositionJointInterface</hardwareInterface>
      <mechanicalReduction>1</mechanicalReduction>
      <motorTorqueConstant>1</motorTorqueConstant>
      <!-- <pulsesPerRevolution>90000</pulsesPerRevolution> -->
    </actuator>
  </transmission>
  <link name="iri_wam_link_4">
    <inertial>
      <mass value="2.0824"/>
      <origin rpy="0 0 0" xyz="-0.045 -0.15 0"/>
      <inertia ixx="1.0" ixy="0.0" ixz="0.0" iyy="1.0" iyz="0.0" izz="1.0"/>
    </inertial>
    <visual>
      <origin rpy="0 0 0" xyz="0.0 0.0 0.0"/>
      <geometry name="iri_wam_link_4_visual">
        <mesh filename="package://iri_wam_description/mesh/wam4.stl" scale="1.0 1.0 1.0"/>
      </geometry>
      <material name="Grey">
        <color rgba="0.75 0.75 0.75 1.0"/>
      </material>
    </visual>
    <collision>
      <origin rpy="0 0 0" xyz="0.0 0.0 0.0"/>
      <geometry name="iri_wam_link_4_collision">
        <mesh filename="package://iri_wam_description/mesh/wam4_collision.stl" scale="1.0 1.0 1.0"/>
        <!--                <box size="0.10 0.10 0.10"/> -->
      </geometry>
      <contact_coefficients kd="1.0" kp="1000.0" mu="0"/>
    </collision>
  </link>
  <gazebo reference="iri_wam_link_4">
    <material>Gazebo/Grey</material>
    <selfCollide>true</selfCollide>
  </gazebo>
  <joint name="iri_wam_joint_4" type="revolute">
    <parent link="iri_wam_link_3"/>
    <child link="iri_wam_link_4"/>
    <origin rpy="-1.57079632679 0 0" xyz="0.045 0.0 0.55"/>
    <axis xyz="0 0 1"/>
    <limit effort="35" lower="-0.9" upper="3.1" velocity="0.5"/>
    <!-- <safety_controller k_velocity="0.5"/> -->
    <dynamics damping="100"/>
  </joint>
  <transmission name="tran_4">
    <type>transmission_interface/SimpleTransmission</type>
    <joint name="iri_wam_joint_4"/>
    <actuator name="motor_4">
      <hardwareInterface>PositionJointInterface</hardwareInterface>
      <mechanicalReduction>1</mechanicalReduction>
      <motorTorqueConstant>1</motorTorqueConstant>
      <!-- <pulsesPerRevolution>90000</pulsesPerRevolution> -->
    </actuator>
  </transmission>
  <link name="iri_wam_link_5">
    <inertial>
      <mass value="0.3067"/>
      <origin rpy="0 0 0" xyz="0 0 0"/>
      <inertia ixx="1.0" ixy="0.0" ixz="0.0" iyy="1.0" iyz="0.0" izz="1.0"/>
    </inertial>
    <visual>
      <origin rpy="0 0 0" xyz="0.0 0.0 0.0"/>
      <geometry name="iri_wam_link_5_visual">
        <mesh filename="package://iri_wam_description/mesh/wam5.stl" scale="1.0 1.0 1.0"/>
      </geometry>
      <material name="Grey">
        <color rgba="0.75 0.75 0.75 1.0"/>
      </material>
    </visual>
    <collision>
      <origin rpy="0 0 0" xyz="0.0 0.0 0.0"/>
      <geometry name="iri_wam_link_5_collision">
        <mesh filename="package://iri_wam_description/mesh/wam5_collision.stl" scale="1.0 1.0 1.0"/>
        <!--                <box size="0.10 0.10 0.10"/> -->
      </geometry>
      <contact_coefficients kd="1.0" kp="1000.0" mu="0"/>
    </collision>
  </link>
  <gazebo reference="iri_wam_link_5">
    <material>Gazebo/Grey</material>
    <selfCollide>true</selfCollide>
  </gazebo>
  <joint name="iri_wam_joint_5" type="revolute">
    <parent link="iri_wam_link_4"/>
    <child link="iri_wam_link_5"/>
    <origin rpy="1.57079632679 0 0" xyz="-0.045 -0.3 0.0"/>
    <axis xyz="0 0 1"/>
    <limit effort="30" lower="-4.76" upper="1.24" velocity="0.5"/>
    <!-- <safety_controller k_velocity="0.5"/> -->
    <dynamics damping="100"/>
  </joint>
  <transmission name="tran_5">
    <type>transmission_interface/SimpleTransmission</type>
    <joint name="iri_wam_joint_5"/>
    <actuator name="motor_5">
      <hardwareInterface>PositionJointInterface</hardwareInterface>
      <mechanicalReduction>1</mechanicalReduction>
      <motorTorqueConstant>1</motorTorqueConstant>
      <!-- <pulsesPerRevolution>90000</pulsesPerRevolution> -->
    </actuator>
  </transmission>
  <link name="iri_wam_link_6">
    <inertial>
      <mass value="0.4278"/>
      <origin rpy="0 0 0" xyz="0 0 0"/>
      <inertia ixx="1.0" ixy="0.0" ixz="0.0" iyy="1.0" iyz="0.0" izz="1.0"/>
    </inertial>
    <visual>
      <origin rpy="0 0 0" xyz="0.0 0.0 0.0"/>
      <geometry name="iri_wam_link_6_visual">
        <mesh filename="package://iri_wam_description/mesh/wam6.stl" scale="1.0 1.0 1.0"/>
      </geometry>
      <material name="Grey">
        <color rgba="0.75 0.75 0.75 1.0"/>
      </material>
    </visual>
    <collision>
      <origin rpy="0 0 0" xyz="0.0 0.0 0.0"/>
      <geometry name="iri_wam_link_6_collision">
        <mesh filename="package://iri_wam_description/mesh/wam6_collision.stl" scale="1.0 1.0 1.0"/>
        <!--                <box size="0.10 0.10 0.10"/> -->
      </geometry>
      <contact_coefficients kd="1.0" kp="1000.0" mu="0"/>
    </collision>
  </link>
  <gazebo reference="iri_wam_link_6">
    <material>Gazebo/Grey</material>
    <selfCollide>true</selfCollide>
  </gazebo>
  <joint name="iri_wam_joint_6" type="revolute">
    <parent link="iri_wam_link_5"/>
    <child link="iri_wam_link_6"/>
    <origin rpy="-1.57079632679 0 0" xyz="0.0 0.0 0.0"/>
    <axis xyz="0 0 1"/>
    <limit effort="30" lower="-1.6" upper="1.6" velocity="0.5"/>
    <!-- <safety_controller k_velocity="0.5"/> -->
    <dynamics damping="100"/>
  </joint>
  <transmission name="tran_6">
    <type>transmission_interface/SimpleTransmission</type>
    <joint name="iri_wam_joint_6"/>
    <actuator name="motor_6">
      <hardwareInterface>PositionJointInterface</hardwareInterface>
      <mechanicalReduction>1</mechanicalReduction>
      <motorTorqueConstant>1</motorTorqueConstant>
      <!-- <pulsesPerRevolution>90000</pulsesPerRevolution> -->
    </actuator>
  </transmission>
  <link name="iri_wam_link_7">
    <inertial>
      <mass value="0.0557"/>
      <origin rpy="0 0 0" xyz="0 0 0"/>
      <inertia ixx="1.0" ixy="0.0" ixz="0.0" iyy="1.0" iyz="0.0" izz="1.0"/>
    </inertial>
    <visual>
      <origin rpy="0 0 0" xyz="0.0 0.0 0.0"/>
      <geometry name="iri_wam_link_7_visual">
        <mesh filename="package://iri_wam_description/mesh/wam7.stl" scale="1.0 1.0 1.0"/>
      </geometry>
      <material name="Grey">
        <color rgba="0.75 0.75 0.75 1.0"/>
      </material>
    </visual>
    <collision>
      <origin rpy="0 0 0" xyz="0.0 0.0 0.0"/>
      <geometry name="iri_wam_link_7_collision">
        <mesh filename="package://iri_wam_description/mesh/wam7_collision.stl" scale="1.0 1.0 1.0"/>
        <!--                <box size="0.10 0.10 0.10"/> -->
      </geometry>
      <contact_coefficients kd="1.0" kp="1000.0" mu="0"/>
    </collision>
  </link>
  <gazebo reference="iri_wam_link_7">
    <material>Gazebo/Grey</material>
    <selfCollide>true</selfCollide>
  </gazebo>
  <joint name="iri_wam_joint_7" type="revolute">
    <parent link="iri_wam_link_6"/>
    <child link="iri_wam_link_7"/>
    <origin rpy="1.57079632679 0 0" xyz="0.0 0.0 0.0"/>
    <axis xyz="0 0 1"/>
    <limit effort="30" lower="-3.0" upper="3.0" velocity="0.5"/>
    <!-- <safety_controller k_velocity="0.5"/> -->
    <dynamics damping="100"/>
  </joint>
  <transmission name="tran_7">
    <type>transmission_interface/SimpleTransmission</type>
    <joint name="iri_wam_joint_7"/>
    <actuator name="motor_7">
      <hardwareInterface>PositionJointInterface</hardwareInterface>
      <mechanicalReduction>1</mechanicalReduction>
      <motorTorqueConstant>1</motorTorqueConstant>
      <!-- <pulsesPerRevolution>90000</pulsesPerRevolution> -->
    </actuator>
  </transmission>
  <link name="iri_wam_link_tcp"/>
  <joint name="iri_wam_joint_tcp" type="fixed">
    <parent link="iri_wam_link_7"/>
    <child link="iri_wam_link_tcp"/>
    <origin rpy="0 0 0" xyz="0.0 0.0 0.06"/>
  </joint>
</robot>

